Workbook
Name Slicer_Region: #N/A
Name Slicer_Year: #N/A

Sheet Requirements1
A1: REQUIREMENTS!
A2: This will be the guide for your works:
A4: 1) Compute the HDI per record using the standard UNDP formula (don’t need to show the calculation in the dashboard)
A5: 2) Summary Statistics by Year and Sex
A6: 3) Trend Visualization (Over Time)
A7: 4) HDI by Sex Comparison
A8: 5) Insights - Highlight best and worst performing years or sex group - or other insights
A9: 6) Interactive Elements
A10: 7) Design and Clarity
A12: Human Development Index (HDI) components:
A13: 🩺Life expectancy at birth
A14: 🎓Mean years of schooling for adults
... A16: 💰Gross National Income (GNI) per capita

Sheet Original data
A1: Region | B1: Year | C1: SEX | D1: Life Expectancy | E1: Expected Schooling | F1: Mean schooling | G1: Gross National Income per capita in pesos
A2: ARMM | B2: 2018 | C2: Female | D2: 69.31 | E2: 11.96 | F2: 6.235 | G2: 174182.03
A3: CAR | B3: 2018 | C3: Female | D3: 76.57 | E3: 14.16 | F3: 9.539 | G3: 409976.92
A4: Region I | B4: 2018 | C4: Female | D4: 72.74 | E4: 13.16 | F4: 9.299 | G4: 430996.89
A5: Region II | B5: 2018 | C5: Female | D5: 74.63 | E5: 13.65 | F5: 8.409 | G5: 356773.41
A6: Region III | B6: 2018 | C6: Female | D6: 74.96 | E6: 12.85 | F6: 9.002 | G6: 484007.73 | I6: =( EYSI + MYSI ) / 2
A7: Region IVA | B7: 2018 | C7: Female | D7: 74.48 | E7: 13.06 | F7: 9.479 | G7: 497253.96 | I7: =([@EYSI]+[@MYSI])/2
A8: Region IVB | B8: 2018 | C8: Female | D8: 72.7 | E8: 13.41 | F8: 8.333 | G8: 309544.19
A9: Region IX | B9: 2018 | C9: Female | D9: 73.44 | E9: 13.34 | F9: 7.73 | G9: 293272.11 | I9: =( LN( [@[GNI_USD]] ) - LN(100) ) / ( LN(75000) - LN(100) )
A10: NCR | B10: 2018 | C10: Female | D10: 76.79 | E10: 13.56 | F10: 10.52 | G10: 562899.37 | I10: =( LN( [@[GNI per capita in USD]] ) - LN(100) ) / ( LN(75000) - LN(100) )
A11: Region V | B11: 2018 | C11: Female | D11: 71.99 | E11: 13.28 | F11: 8.483 | G11: 305240.77 | I11: [@[GNI per capita in USD]]
A12: Region VI | B12: 2018 | C12: Female | D12: 70.86 | E12: 13.52 | F12: 8.6 | G12: 324115.81
A13: Region VII | B13: 2018 | C13: Female | D13: 73.19 | E13: 13.38 | F13: 8.326 | G13: 357845.34 | I13: =POWER( ( Health_Index * Education_Index * Income_Index ), 1/3 )
A14: Region VIII | B14: 2018 | C14: Female | D14: 72.82 | E14: 13.9 | F14: 8.405 | G14: 327700.76 | I14: =POWER(([@[Health Index]]*[@[Education Index]]*[@[Income Index]]), 1/3)
A15: Region X | B15: 2018 | C15: Female | D15: 73.15 | E15: 13.29 | F15: 8.749 | G15: 342099.24
A16: Region XI | B16: 2018 | C16: Female | D16: 74.5 | E16: 13.01 | F16: 8.454 | G16: 305240.77 | I16: =VLOOKUP(B2, exchange_rates, 2, FALSE)
A17: Region XII | B17: 2018 | C17: Female | D17: 70.36 | E17: 12.95 | F17: 8.058 | G17: 288040.44
A18: Region XIII | B18: 2018 | C18: Female | D18: 73.89 | E18: 13.3 | F18: 8.583 | G18: 357130.36
A19: ARMM | B19: 2018 | C19: Male | D19: 66.35 | E19: 10.85 | F19: 5.652 | G19: 250410.33
A20: CAR | B20: 2018 | C20: Male | D20: 72.25 | E20: 12.69 | F20: 8.763 | G20: 612838.15
A21: Region I | B21: 2018 | C21: Male | D21: 69.15 | E21: 12.5 | F21: 8.734 | G21: 645548.84
A22: Region II | B22: 2018 | C22: Male | D22: 70.68 | E22: 12 | F22: 7.828 | G22: 529588.81
A23: Region III | B23: 2018 | C23: Male | D23: 70.95 | E23: 12.06 | F23: 8.688 | G23: 728582.51
A24: Region IVA | B24: 2018 | C24: Male | D24: 70.56 | E24: 12.46 | F24: 9.112 | G24: 750020.75
A25: Region IVB | B25: 2018 | C25: Male | D25: 69.12 | E25: 12.14 | F25: 7.603 | G25: 456733.87
A26: Region IX | B26: 2018 | C26: Male | D26: 69.72 | E26: 12.21 | F26: 7.261 | G26: 431428.1
A27: NCR | B27: 2018 | C27: Male | D27: 72.43 | E27: 12.8 | F27: 10.22 | G27: 853291.2
A28: Region V | B28: 2018 | C28: Male | D28: 68.55 | E28: 12.29 | F28: 7.857 | G28: 449933.99
... A171: Region XIII | B171: 2022 | C171: Male | D171: 71.53 | E171: 12.62 | F171: 8.033 | G171: 612739.69

Sheet Dashboard
H3: Summary: 5-year Average
H30: Detailed Breakdown

Sheet Pivot Tables
B3: Table 1: Average HDI by Region | F3: Table 2: Average HDI by Sex | J3: Table 3: Average HDI by Year
B4: Row Labels | C4: Average of HDI | F4: Row Labels | G4: Average of HDI | J4: Row Labels | K4: Average of HDI
B5: ARMM | C5: 0.60870235 | F5: Female | G5: 0.70028166 | J5: 2018 | K5: 0.69179443
B6: Region XII | C6: 0.66885668 | F6: Male | G6: 0.68829624 | J6: 2019 | K6: 0.70117026
B7: Region IX | C7: 0.67020434 | F7: Grand Total | G7: 0.69428895 | J7: 2020 | K7: 0.69425392
B8: Region V | C8: 0.67580904 | J8: 2021 | K8: 0.68452477
B9: Region IVB | C9: 0.68310311 | J9: 2022 | K9: 0.69970136
B10: Region VIII | C10: 0.68874695 | J10: Grand Total | K10: 0.69428895
B11: Region VII | C11: 0.68929911
B12: Region VI | C12: 0.6932284 | F12: Table 4: Average HDI by Region by Year
B13: Region XI | C13: 0.69613645 | F13: Average of HDI | G13: Column Labels
B14: Region X | C14: 0.69838352 | F14: Row Labels | G14: ARMM | H14: CAR | I14: NCR | J14: Region I | K14: Region II | L14: Region III | M14: Region IVA | N14: Region IVB | O14: Region IX | P14: Region V | Q14: Region VI | R14: Region VII | S14: Region VIII | T14: Region X | U14: Region XI | V14: Region XII | W14: Region XIII | X14: Grand Total
B15: Region XIII | C15: 0.69922565 | F15: 2018 | G15: 0.59445866 | H15: 0.73030977 | I15: 0.76057535 | J15: 0.70980605 | K15: 0.69631711 | L15: 0.71915101 | M15: 0.72728485 | N15: 0.67862024 | O15: 0.67288431 | P15: 0.67760585 | Q15: 0.68002034 | R15: 0.69070047 | S15: 0.68763558 | T15: 0.69100404 | U15: 0.68992624 | V15: 0.66015588 | W15: 0.69404961 | X15: 0.69179443
B16: Region II | C16: 0.70431594 | F16: 2019 | G16: 0.60895235 | H16: 0.73934465 | I16: 0.7634554 | J16: 0.71608448 | K16: 0.70856504 | L16: 0.72734896 | M16: 0.73302115 | N16: 0.68893631 | O16: 0.67944866 | P16: 0.68459662 | Q16: 0.69477615 | R16: 0.69803908 | S16: 0.69623935 | T16: 0.70285179 | U16: 0.70109403 | V16: 0.67235085 | W16: 0.7047895 | X16: 0.70117026
B17: Region I | C17: 0.7058681 | F17: 2020 | G17: 0.60842272 | H17: 0.73135991 | I17: 0.74915629 | J17: 0.70596496 | K17: 0.70430186 | L17: 0.71879051 | M17: 0.72211579 | N17: 0.68301979 | O17: 0.67008822 | P17: 0.67564219 | Q17: 0.69322938 | R17: 0.68922383 | S17: 0.68860451 | T17: 0.69840655 | U17: 0.69603319 | V17: 0.66878913 | W17: 0.69916781 | X17: 0.69425392
B18: Region III | C18: 0.71862099 | F18: 2021 | G18: 0.60606605 | H18: 0.72038326 | I18: 0.73164512 | J18: 0.69262544 | K18: 0.69720674 | L18: 0.70692827 | M18: 0.70792317 | N18: 0.67444621 | O18: 0.65818308 | P18: 0.66416743 | Q18: 0.68872897 | R18: 0.67766292 | S18: 0.67837819 | T18: 0.69103174 | U18: 0.68825284 | V18: 0.66251823 | W18: 0.69077342 | X18: 0.68452477
B19: Region IVA | C19: 0.72199057 | F19: 2022 | G19: 0.62561198 | H19: 0.73538267 | I19: 0.74049202 | J19: 0.70485959 | K19: 0.71518896 | L19: 0.72088619 | M19: 0.71960789 | N19: 0.69049298 | O19: 0.67041743 | P19: 0.67703311 | Q19: 0.70938718 | R19: 0.69086925 | S19: 0.69287711 | T19: 0.70862349 | U19: 0.70537597 | V19: 0.68046933 | W19: 0.7073479 | X19: 0.69970136
B20: CAR | C20: 0.73135605 | F20: Grand Total | G20: 0.60870235 | H20: 0.73135605 | I20: 0.74906483 | J20: 0.7058681 | K20: 0.70431594 | L20: 0.71862099 | M20: 0.72199057 | N20: 0.68310311 | O20: 0.67020434 | P20: 0.67580904 | Q20: 0.6932284 | R20: 0.68929911 | S20: 0.68874695 | T20: 0.69838352 | U20: 0.69613645 | V20: 0.66885668 | W20: 0.69922565 | X20: 0.69428895
B21: NCR | C21: 0.74906483
B22: Grand Total | C22: 0.69428895 | F22: Table 5: Average HDI by Sex by Year
F23: Average of HDI | G23: Column Labels
F24: Row Labels | G24: Female | H24: Male | I24: Grand Total
F25: 2018 | G25: 0.69824046 | H25: 0.6853484 | I25: 0.69179443
F26: 2019 | G26: 0.70823359 | H26: 0.69410693 | I26: 0.70117026
F27: 2020 | G27: 0.7017005 | H27: 0.68680735 | I27: 0.69425392
F28: 2021 | G28: 0.69364665 | H28: 0.67540289 | I28: 0.68452477
F29: 2022 | G29: 0.69958709 | H29: 0.69981563 | I29: 0.69970136
F30: Grand Total | G30: 0.70028166 | H30: 0.68829624 | I30: 0.69428895
F32: Table 6: Average HDI by Region by Sex
F33: Average of HDI | G33: Column Labels
F34: Row Labels | G34: Female | H34: Male | I34: Grand Total
F35: ARMM | G35: 0.60049128 | H35: 0.58842604 | I35: 0.59445866
F36: CAR | G36: 0.74121581 | H36: 0.71940373 | I36: 0.73030977
F37: NCR | G37: 0.76542987 | H37: 0.75572082 | I37: 0.76057535
F38: Region I | G38: 0.71445945 | H38: 0.70515265 | I38: 0.70980605
F39: Region II | G39: 0.70671394 | H39: 0.68592028 | I39: 0.69631711
F40: Region III | G40: 0.72391429 | H40: 0.71438772 | I40: 0.71915101
F41: Region IVA | G41: 0.73112306 | H41: 0.72344665 | I41: 0.72728485
F42: Region IVB | G42: 0.68713639 | H42: 0.6701041 | I42: 0.67862024
F43: Region IX | G43: 0.67941806 | H43: 0.66635056 | I43: 0.67288431
...

Sheet Data
B3: Region | C3: Year | D3: Sex | E3: Life Expectancy | F3: Health Index | G3: Expected Schooling | H3: Expected Schooling Index | I3: Mean Schooling | J3: Mean Schooling Index | K3: Education Index | L3: GNI per capita (PHP) | M3: GNI per capita (USD) | N3: Income Index | O3: HDI | Q3: Year | R3: USD to PHP
B4: ARMM | C4: 2018 | D4: Female | E4: 69.31 | F4: =(Data!$E4-20)/65 -> 0.75861538 | G4: 11.96 | H4: =Data!$G4/18 -> 0.66444444 | I4: 6.235 | J4: =Data!$I4/15 -> 0.41566667 | K4: =(Data!$H4+Data!$J4)/2 -> 0.54005556 | L4: 174182.03 | M4: =L4/VLOOKUP(C4, exchange_rates[], 2, FALSE) -> 3307.6723 | N4: =( LN( Data!$M4 ) - LN(100) ) / ( LN(75000) - LN(100) ) -> 0.5285183 | O4: =POWER((Data!$F4*Data!$K4*Data!$N4), 1/3) -> 0.60049128 | Q4: 2018 | R4: 52.66
B5: CAR | C5: 2018 | D5: Female | E5: 76.57 | F5: =(Data!$E5-20)/65 -> 0.87030769 | G5: 14.16 | H5: =Data!$G5/18 -> 0.78666667 | I5: 9.539 | J5: =Data!$I5/15 -> 0.63593333 | K5: =(Data!$H5+Data!$J5)/2 -> 0.7113 | L5: 409976.92 | M5: =L5/VLOOKUP(C5, exchange_rates[], 2, FALSE) -> 7785.3575 | N5: =( LN( Data!$M5 ) - LN(100) ) / ( LN(75000) - LN(100) ) -> 0.657822 | O5: =POWER((Data!$F5*Data!$K5*Data!$N5), 1/3) -> 0.74121581 | Q5: 2019 | R5: 51.8
B6: Region I | C6: 2018 | D6: Female | E6: 72.74 | F6: =(Data!$E6-20)/65 -> 0.81138462 | G6: 13.16 | H6: =Data!$G6/18 -> 0.73111111 | I6: 9.299 | J6: =Data!$I6/15 -> 0.61993333 | K6: =(Data!$H6+Data!$J6)/2 -> 0.67552222 | L6: 430996.89 | M6: =L6/VLOOKUP(C6, exchange_rates[], 2, FALSE) -> 8184.5213 | N6: =( LN( Data!$M6 ) - LN(100) ) / ( LN(75000) - LN(100) ) -> 0.66537479 | O6: =POWER((Data!$F6*Data!$K6*Data!$N6), 1/3) -> 0.71445945 | Q6: 2020 | R6: 49.63
B7: Region II | C7: 2018 | D7: Female | E7: 74.63 | F7: =(Data!$E7-20)/65 -> 0.84046154 | G7: 13.65 | H7: =Data!$G7/18 -> 0.75833333 | I7: 8.409 | J7: =Data!$I7/15 -> 0.5606 | K7: =(Data!$H7+Data!$J7)/2 -> 0.65946667 | L7: 356773.41 | M7: =L7/VLOOKUP(C7, exchange_rates[], 2, FALSE) -> 6775.0363 | N7: =( LN( Data!$M7 ) - LN(100) ) / ( LN(75000) - LN(100) ) -> 0.63682526 | O7: =POWER((Data!$F7*Data!$K7*Data!$N7), 1/3) -> 0.70671394 | Q7: 2021 | R7: 48
B8: Region III | C8: 2018 | D8: Female | E8: 74.96 | F8: =(Data!$E8-20)/65 -> 0.84553846 | G8: 12.85 | H8: =Data!$G8/18 -> 0.71388889 | I8: 9.002 | J8: =Data!$I8/15 -> 0.60013333 | K8: =(Data!$H8+Data!$J8)/2 -> 0.65701111 | L8: 484007.73 | M8: =L8/VLOOKUP(C8, exchange_rates[], 2, FALSE) -> 9191.1836 | N8: =( LN( Data!$M8 ) - LN(100) ) / ( LN(75000) - LN(100) ) -> 0.68289725 | O8: =POWER((Data!$F8*Data!$K8*Data!$N8), 1/3) -> 0.72391429 | Q8: 2022 | R8: 54.48
B9: Region IVA | C9: 2018 | D9: Female | E9: 74.48 | F9: =(Data!$E9-20)/65 -> 0.83815385 | G9: 13.06 | H9: =Data!$G9/18 -> 0.72555556 | I9: 9.479 | J9: =Data!$I9/15 -> 0.63193333 | K9: =(Data!$H9+Data!$J9)/2 -> 0.67874444 | L9: 497253.96 | M9: =L9/VLOOKUP(C9, exchange_rates[], 2, FALSE) -> 9442.7261 | N9: =( LN( Data!$M9 ) - LN(100) ) / ( LN(75000) - LN(100) ) -> 0.68697576 | O9: =POWER((Data!$F9*Data!$K9*Data!$N9), 1/3) -> 0.73112306
B10: Region IVB | C10: 2018 | D10: Female | E10: 72.7 | F10: =(Data!$E10-20)/65 -> 0.81076923 | G10: 13.41 | H10: =Data!$G10/18 -> 0.745 | I10: 8.333 | J10: =Data!$I10/15 -> 0.55553333 | K10: =(Data!$H10+Data!$J10)/2 -> 0.65026667 | L10: 309544.19 | M10: =L10/VLOOKUP(C10, exchange_rates[], 2, FALSE) -> 5878.1655 | N10: =( LN( Data!$M10 ) - LN(100) ) / ( LN(75000) - LN(100) ) -> 0.61537534 | O10: =POWER((Data!$F10*Data!$K10*Data!$N10), 1/3) -> 0.68713639
B11: Region IX | C11: 2018 | D11: Female | E11: 73.44 | F11: =(Data!$E11-20)/65 -> 0.82215385 | G11: 13.34 | H11: =Data!$G11/18 -> 0.74111111 | I11: 7.73 | J11: =Data!$I11/15 -> 0.51533333 | K11: =(Data!$H11+Data!$J11)/2 -> 0.62822222 | L11: 293272.11 | M11: =L11/VLOOKUP(C11, exchange_rates[], 2, FALSE) -> 5569.1627 | N11: =( LN( Data!$M11 ) - LN(100) ) / ( LN(75000) - LN(100) ) -> 0.60721833 | O11: =POWER((Data!$F11*Data!$K11*Data!$N11), 1/3) -> 0.67941806
B12: NCR | C12: 2018 | D12: Female | E12: 76.79 | F12: =(Data!$E12-20)/65 -> 0.87369231 | G12: 13.56 | H12: =Data!$G12/18 -> 0.75333333 | I12: 10.52 | J12: =Data!$I12/15 -> 0.70133333 | K12: =(Data!$H12+Data!$J12)/2 -> 0.72733333 | L12: 562899.37 | M12: =L12/VLOOKUP(C12, exchange_rates[], 2, FALSE) -> 10689.316 | N12: =( LN( Data!$M12 ) - LN(100) ) / ( LN(75000) - LN(100) ) -> 0.70570667 | O12: =POWER((Data!$F12*Data!$K12*Data!$N12), 1/3) -> 0.76542987
B13: Region V | C13: 2018 | D13: Female | E13: 71.99 | F13: =(Data!$E13-20)/65 -> 0.79984615 | G13: 13.28 | H13: =Data!$G13/18 -> 0.73777778 | I13: 8.483 | J13: =Data!$I13/15 -> 0.56553333 | K13: =(Data!$H13+Data!$J13)/2 -> 0.65165556 | L13: 305240.77 | M13: =L13/VLOOKUP(C13, exchange_rates[], 2, FALSE) -> 5796.4446 | N13: =( LN( Data!$M13 ) - LN(100) ) / ( LN(75000) - LN(100) ) -> 0.61326056 | O13: =POWER((Data!$F13*Data!$K13*Data!$N13), 1/3) -> 0.68373823
B14: Region VI | C14: 2018 | D14: Female | E14: 70.86 | F14: =(Data!$E14-20)/65 -> 0.78246154 | G14: 13.52 | H14: =Data!$G14/18 -> 0.75111111 | I14: 8.6 | J14: =Data!$I14/15 -> 0.57333333 | K14: =(Data!$H14+Data!$J14)/2 -> 0.66222222 | L14: 324115.81 | M14: =L14/VLOOKUP(C14, exchange_rates[], 2, FALSE) -> 6154.8767 | N14: =( LN( Data!$M14 ) - LN(100) ) / ( LN(75000) - LN(100) ) -> 0.62232391 | O14: =POWER((Data!$F14*Data!$K14*Data!$N14), 1/3) -> 0.68574252
B15: Region VII | C15: 2018 | D15: Female | E15: 73.19 | F15: =(Data!$E15-20)/65 -> 0.81830769 | G15: 13.38 | H15: =Data!$G15/18 -> 0.74333333 | I15: 8.326 | J15: =Data!$I15/15 -> 0.55506667 | K15: =(Data!$H15+Data!$J15)/2 -> 0.6492 | L15: 357845.34 | M15: =L15/VLOOKUP(C15, exchange_rates[], 2, FALSE) -> 6795.3919 | N15: =( LN( Data!$M15 ) - LN(100) ) / ( LN(75000) - LN(100) ) -> 0.63727842 | O15: =POWER((Data!$F15*Data!$K15*Data!$N15), 1/3) -> 0.69696043
B16: Region VIII | C16: 2018 | D16: Female | E16: 72.82 | F16: =(Data!$E16-20)/65 -> 0.81261538 | G16: 13.9 | H16: =Data!$G16/18 -> 0.77222222 | I16: 8.405 | J16: =Data!$I16/15 -> 0.56033333 | K16: =(Data!$H16+Data!$J16)/2 -> 0.66627778 | L16: 327700.76 | M16: =L16/VLOOKUP(C16, exchange_rates[], 2, FALSE) -> 6222.954 | N16: =( LN( Data!$M16 ) - LN(100) ) / ( LN(75000) - LN(100) ) -> 0.62398552 | O16: =POWER((Data!$F16*Data!$K16*Data!$N16), 1/3) -> 0.69647408
B17: Region X | C17: 2018 | D17: Female | E17: 73.15 | F17: =(Data!$E17-20)/65 -> 0.81769231 | G17: 13.29 | H17: =Data!$G17/18 -> 0.73833333 | I17: 8.749 | J17: =Data!$I17/15 -> 0.58326667 | K17: =(Data!$H17+Data!$J17)/2 -> 0.6608 | L17: 342099.24 | M17: =L17/VLOOKUP(C17, exchange_rates[], 2, FALSE) -> 6496.3775 | N17: =( LN( Data!$M17 ) - LN(100) ) / ( LN(75000) - LN(100) ) -> 0.63048092 | O17: =POWER((Data!$F17*Data!$K17*Data!$N17), 1/3) -> 0.69841029
B18: Region XI | C18: 2018 | D18: Female | E18: 74.5 | F18: =(Data!$E18-20)/65 -> 0.83846154 | G18: 13.01 | H18: =Data!$G18/18 -> 0.72277778 | I18: 8.454 | J18: =Data!$I18/15 -> 0.5636 | K18: =(Data!$H18+Data!$J18)/2 -> 0.64318889 | L18: 305240.77 | M18: =L18/VLOOKUP(C18, exchange_rates[], 2, FALSE) -> 5796.4446 | N18: =( LN( Data!$M18 ) - LN(100) ) / ( LN(75000) - LN(100) ) -> 0.61326056 | O18: =POWER((Data!$F18*Data!$K18*Data!$N18), 1/3) -> 0.69154785
B19: Region XII | C19: 2018 | D19: Female | E19: 70.36 | F19: =(Data!$E19-20)/65 -> 0.77476923 | G19: 12.95 | H19: =Data!$G19/18 -> 0.71944444 | I19: 8.058 | J19: =Data!$I19/15 -> 0.5372 | K19: =(Data!$H19+Data!$J19)/2 -> 0.62832222 | L19: 288040.44 | M19: =L19/VLOOKUP(C19, exchange_rates[], 2, FALSE) -> 5469.8146 | N19: =( LN( Data!$M19 ) - LN(100) ) / ( LN(75000) - LN(100) ) -> 0.60449933 | O19: =POWER((Data!$F19*Data!$K19*Data!$N19), 1/3) -> 0.66514582
B20: Region XIII | C20: 2018 | D20: Female | E20: 73.89 | F20: =(Data!$E20-20)/65 -> 0.82907692 | G20: 13.3 | H20: =Data!$G20/18 -> 0.73888889 | I20: 8.583 | J20: =Data!$I20/15 -> 0.5722 | K20: =(Data!$H20+Data!$J20)/2 -> 0.65554444 | L20: 357130.36 | M20: =L20/VLOOKUP(C20, exchange_rates[], 2, FALSE) -> 6781.8147 | N20: =( LN( Data!$M20 ) - LN(100) ) / ( LN(75000) - LN(100) ) -> 0.63697631 | O20: =POWER((Data!$F20*Data!$K20*Data!$N20), 1/3) -> 0.70216646
... B173: Region XIII | C173: 2022 | D173: Male | E173: 71.53 | F173: =(Data!$E173-20)/65 -> 0.79276923 | G173: 12.62 | H173: =Data!$G173/18 -> 0.70111111 | I173: 8.033 | J173: =Data!$I173/15 -> 0.53553333 | K173: =(Data!$H173+Data!$J173)/2 -> 0.61832222 | L173: 612739.69 | M173: =L173/VLOOKUP(C173, exchange_rates[], 2, FALSE) -> 11247.058 | N173: =( LN( Data!$M173 ) - LN(100) ) / ( LN(75000) - LN(100) ) -> 0.71338964 | O173: =POWER((Data!$F173*Data!$K173*Data!$N173), 1/3) -> 0.70452457

Sheet Data backup
A1: Region | B1: Year | C1: SEX | D1: Life Expectancy | E1: Expected Schooling | F1: Mean schooling | G1: GNI per capita (PHP) | H1: GNI per capita (USD) | I1: EYSI | J1: MYSI | K1: Health Index | L1: Education Index | M1: Income Index | N1: HDI | P1: Year | Q1: PHP per USD
A2: ARMM | B2: 2018 | C2: Female | D2: 69.31 | E2: 11.96 | F2: 6.235 | G2: 174182.03 | H2: =G2/VLOOKUP(B2, exchange_rates6[], 2, FALSE) -> 3307.6723 | I2: =HDI_Data5[[#This Row],[Expected Schooling ]]/18 -> 0.66444444 | J2: =HDI_Data5[[#This Row],[Mean schooling ]]/15 -> 0.41566667 | K2: =(HDI_Data5[[#This Row],[Life Expectancy ]]-20)/65 -> 0.75861538 | L2: =(HDI_Data5[[#This Row],[EYSI]]+HDI_Data5[[#This Row],[MYSI]])/2 -> 0.54005556 | M2: =( LN( HDI_Data5[[#This Row],[GNI per capita (USD)]] ) - LN(100) ) / ( LN(75000) - LN(100) ) -> 0.5285183 | N2: =POWER((HDI_Data5[[#This Row],[Health Index]]*HDI_Data5[[#This Row],[Education Index]]*HDI_Data5[[#This Row],[Income Index]]), 1/3) -> 0.60049128 | P2: 2018 | Q2: 52.66
A3: CAR | B3: 2018 | C3: Female | D3: 76.57 | E3: 14.16 | F3: 9.539 | G3: 409976.92 | H3: =G3/VLOOKUP(B3, exchange_rates6[], 2, FALSE) -> 7785.3575 | I3: =HDI_Data5[[#This Row],[Expected Schooling ]]/18 -> 0.78666667 | J3: =HDI_Data5[[#This Row],[Mean schooling ]]/15 -> 0.63593333 | K3: =(HDI_Data5[[#This Row],[Life Expectancy ]]-20)/65 -> 0.87030769 | L3: =(HDI_Data5[[#This Row],[EYSI]]+HDI_Data5[[#This Row],[MYSI]])/2 -> 0.7113 | M3: =( LN( HDI_Data5[[#This Row],[GNI per capita (USD)]] ) - LN(100) ) / ( LN(75000) - LN(100) ) -> 0.657822 | N3: =POWER((HDI_Data5[[#This Row],[Health Index]]*HDI_Data5[[#This Row],[Education Index]]*HDI_Data5[[#This Row],[Income Index]]), 1/3) -> 0.74121581 | P3: 2019 | Q3: 51.8
A4: Region I | B4: 2018 | C4: Female | D4: 72.74 | E4: 13.16 | F4: 9.299 | G4: 430996.89 | H4: =G4/VLOOKUP(B4, exchange_rates6[], 2, FALSE) -> 8184.5213 | I4: =HDI_Data5[[#This Row],[Expected Schooling ]]/18 -> 0.73111111 | J4: =HDI_Data5[[#This Row],[Mean schooling ]]/15 -> 0.61993333 | K4: =(HDI_Data5[[#This Row],[Life Expectancy ]]-20)/65 -> 0.81138462 | L4: =(HDI_Data5[[#This Row],[EYSI]]+HDI_Data5[[#This Row],[MYSI]])/2 -> 0.67552222 | M4: =( LN( HDI_Data5[[#This Row],[GNI per capita (USD)]] ) - LN(100) ) / ( LN(75000) - LN(100) ) -> 0.66537479 | N4: =POWER((HDI_Data5[[#This Row],[Health Index]]*HDI_Data5[[#This Row],[Education Index]]*HDI_Data5[[#This Row],[Income Index]]), 1/3) -> 0.71445945 | P4: 2020 | Q4: 49.63
A5: Region II | B5: 2018 | C5: Female | D5: 74.63 | E5: 13.65 | F5: 8.409 | G5: 356773.41 | H5: =G5/VLOOKUP(B5, exchange_rates6[], 2, FALSE) -> 6775.0363 | I5: =HDI_Data5[[#This Row],[Expected Schooling ]]/18 -> 0.75833333 | J5: =HDI_Data5[[#This Row],[Mean schooling ]]/15 -> 0.5606 | K5: =(HDI_Data5[[#This Row],[Life Expectancy ]]-20)/65 -> 0.84046154 | L5: =(HDI_Data5[[#This Row],[EYSI]]+HDI_Data5[[#This Row],[MYSI]])/2 -> 0.65946667 | M5: =( LN( HDI_Data5[[#This Row],[GNI per capita (USD)]] ) - LN(100) ) / ( LN(75000) - LN(100) ) -> 0.63682526 | N5: =POWER((HDI_Data5[[#This Row],[Health Index]]*HDI_Data5[[#This Row],[Education Index]]*HDI_Data5[[#This Row],[Income Index]]), 1/3) -> 0.70671394 | P5: 2021 | Q5: 48
A6: Region III | B6: 2018 | C6: Female | D6: 74.96 | E6: 12.85 | F6: 9.002 | G6: 484007.73 | H6: =G6/VLOOKUP(B6, exchange_rates6[], 2, FALSE) -> 9191.1836 | I6: =HDI_Data5[[#This Row],[Expected Schooling ]]/18 -> 0.71388889 | J6: =HDI_Data5[[#This Row],[Mean schooling ]]/15 -> 0.60013333 | K6: =(HDI_Data5[[#This Row],[Life Expectancy ]]-20)/65 -> 0.84553846 | L6: =(HDI_Data5[[#This Row],[EYSI]]+HDI_Data5[[#This Row],[MYSI]])/2 -> 0.65701111 | M6: =( LN( HDI_Data5[[#This Row],[GNI per capita (USD)]] ) - LN(100) ) / ( LN(75000) - LN(100) ) -> 0.68289725 | N6: =POWER((HDI_Data5[[#This Row],[Health Index]]*HDI_Data5[[#This Row],[Education Index]]*HDI_Data5[[#This Row],[Income Index]]), 1/3) -> 0.72391429 | P6: 2022 | Q6: 54.48
A7: Region IVA | B7: 2018 | C7: Female | D7: 74.48 | E7: 13.06 | F7: 9.479 | G7: 497253.96 | H7: =G7/VLOOKUP(B7, exchange_rates6[], 2, FALSE) -> 9442.7261 | I7: =HDI_Data5[[#This Row],[Expected Schooling ]]/18 -> 0.72555556 | J7: =HDI_Data5[[#This Row],[Mean schooling ]]/15 -> 0.63193333 | K7: =(HDI_Data5[[#This Row],[Life Expectancy ]]-20)/65 -> 0.83815385 | L7: =(HDI_Data5[[#This Row],[EYSI]]+HDI_Data5[[#This Row],[MYSI]])/2 -> 0.67874444 | M7: =( LN( HDI_Data5[[#This Row],[GNI per capita (USD)]] ) - LN(100) ) / ( LN(75000) - LN(100) ) -> 0.68697576 | N7: =POWER((HDI_Data5[[#This Row],[Health Index]]*HDI_Data5[[#This Row],[Education Index]]*HDI_Data5[[#This Row],[Income Index]]), 1/3) -> 0.73112306
A8: Region IVB | B8: 2018 | C8: Female | D8: 72.7 | E8: 13.41 | F8: 8.333 | G8: 309544.19 | H8: =G8/VLOOKUP(B8, exchange_rates6[], 2, FALSE) -> 5878.1655 | I8: =HDI_Data5[[#This Row],[Expected Schooling ]]/18 -> 0.745 | J8: =HDI_Data5[[#This Row],[Mean schooling ]]/15 -> 0.55553333 | K8: =(HDI_Data5[[#This Row],[Life Expectancy ]]-20)/65 -> 0.81076923 | L8: =(HDI_Data5[[#This Row],[EYSI]]+HDI_Data5[[#This Row],[MYSI]])/2 -> 0.65026667 | M8: =( LN( HDI_Data5[[#This Row],[GNI per capita (USD)]] ) - LN(100) ) / ( LN(75000) - LN(100) ) -> 0.61537534 | N8: =POWER((HDI_Data5[[#This Row],[Health Index]]*HDI_Data5[[#This Row],[Education Index]]*HDI_Data5[[#This Row],[Income Index]]), 1/3) -> 0.68713639
A9: Region IX | B9: 2018 | C9: Female | D9: 73.44 | E9: 13.34 | F9: 7.73 | G9: 293272.11 | H9: =G9/VLOOKUP(B9, exchange_rates6[], 2, FALSE) -> 5569.1627 | I9: =HDI_Data5[[#This Row],[Expected Schooling ]]/18 -> 0.74111111 | J9: =HDI_Data5[[#This Row],[Mean schooling ]]/15 -> 0.51533333 | K9: =(HDI_Data5[[#This Row],[Life Expectancy ]]-20)/65 -> 0.82215385 | L9: =(HDI_Data5[[#This Row],[EYSI]]+HDI_Data5[[#This Row],[MYSI]])/2 -> 0.62822222 | M9: =( LN( HDI_Data5[[#This Row],[GNI per capita (USD)]] ) - LN(100) ) / ( LN(75000) - LN(100) ) -> 0.60721833 | N9: =POWER((HDI_Data5[[#This Row],[Health Index]]*HDI_Data5[[#This Row],[Education Index]]*HDI_Data5[[#This Row],[Income Index]]), 1/3) -> 0.67941806
A10: NCR | B10: 2018 | C10: Female | D10: 76.79 | E10: 13.56 | F10: 10.52 | G10: 562899.37 | H10: =G10/VLOOKUP(B10, exchange_rates6[], 2, FALSE) -> 10689.316 | I10: =HDI_Data5[[#This Row],[Expected Schooling ]]/18 -> 0.75333333 | J10: =HDI_Data5[[#This Row],[Mean schooling ]]/15 -> 0.70133333 | K10: =(HDI_Data5[[#This Row],[Life Expectancy ]]-20)/65 -> 0.87369231 | L10: =(HDI_Data5[[#This Row],[EYSI]]+HDI_Data5[[#This Row],[MYSI]])/2 -> 0.72733333 | M10: =( LN( HDI_Data5[[#This Row],[GNI per capita (USD)]] ) - LN(100) ) / ( LN(75000) - LN(100) ) -> 0.70570667 | N10: =POWER((HDI_Data5[[#This Row],[Health Index]]*HDI_Data5[[#This Row],[Education Index]]*HDI_Data5[[#This Row],[Income Index]]), 1/3) -> 0.76542987
A11: Region V | B11: 2018 | C11: Female | D11: 71.99 | E11: 13.28 | F11: 8.483 | G11: 305240.77 | H11: =G11/VLOOKUP(B11, exchange_rates6[], 2, FALSE) -> 5796.4446 | I11: =HDI_Data5[[#This Row],[Expected Schooling ]]/18 -> 0.73777778 | J11: =HDI_Data5[[#This Row],[Mean schooling ]]/15 -> 0.56553333 | K11: =(HDI_Data5[[#This Row],[Life Expectancy ]]-20)/65 -> 0.79984615 | L11: =(HDI_Data5[[#This Row],[EYSI]]+HDI_Data5[[#This Row],[MYSI]])/2 -> 0.65165556 | M11: =( LN( HDI_Data5[[#This Row],[GNI per capita (USD)]] ) - LN(100) ) / ( LN(75000) - LN(100) ) -> 0.61326056 | N11: =POWER((HDI_Data5[[#This Row],[Health Index]]*HDI_Data5[[#This Row],[Education Index]]*HDI_Data5[[#This Row],[Income Index]]), 1/3) -> 0.68373823
A12: Region VI | B12: 2018 | C12: Female | D12: 70.86 | E12: 13.52 | F12: 8.6 | G12: 324115.81 | H12: =G12/VLOOKUP(B12, exchange_rates6[], 2, FALSE) -> 6154.8767 | I12: =HDI_Data5[[#This Row],[Expected Schooling ]]/18 -> 0.75111111 | J12: =HDI_Data5[[#This Row],[Mean schooling ]]/15 -> 0.57333333 | K12: =(HDI_Data5[[#This Row],[Life Expectancy ]]-20)/65 -> 0.78246154 | L12: =(HDI_Data5[[#This Row],[EYSI]]+HDI_Data5[[#This Row],[MYSI]])/2 -> 0.66222222 | M12: =( LN( HDI_Data5[[#This Row],[GNI per capita (USD)]] ) - LN(100) ) / ( LN(75000) - LN(100) ) -> 0.62232391 | N12: =POWER((HDI_Data5[[#This Row],[Health Index]]*HDI_Data5[[#This Row],[Education Index]]*HDI_Data5[[#This Row],[Income Index]]), 1/3) -> 0.68574252
A13: Region VII | B13: 2018 | C13: Female | D13: 73.19 | E13: 13.38 | F13: 8.326 | G13: 357845.34 | H13: =G13/VLOOKUP(B13, exchange_rates6[], 2, FALSE) -> 6795.3919 | I13: =HDI_Data5[[#This Row],[Expected Schooling ]]/18 -> 0.74333333 | J13: =HDI_Data5[[#This Row],[Mean schooling ]]/15 -> 0.55506667 | K13: =(HDI_Data5[[#This Row],[Life Expectancy ]]-20)/65 -> 0.81830769 | L13: =(HDI_Data5[[#This Row],[EYSI]]+HDI_Data5[[#This Row],[MYSI]])/2 -> 0.6492 | M13: =( LN( HDI_Data5[[#This Row],[GNI per capita (USD)]] ) - LN(100) ) / ( LN(75000) - LN(100) ) -> 0.63727842 | N13: =POWER((HDI_Data5[[#This Row],[Health Index]]*HDI_Data5[[#This Row],[Education Index]]*HDI_Data5[[#This Row],[Income Index]]), 1/3) -> 0.69696043
A14: Region VIII | B14: 2018 | C14: Female | D14: 72.82 | E14: 13.9 | F14: 8.405 | G14: 327700.76 | H14: =G14/VLOOKUP(B14, exchange_rates6[], 2, FALSE) -> 6222.954 | I14: =HDI_Data5[[#This Row],[Expected Schooling ]]/18 -> 0.77222222 | J14: =HDI_Data5[[#This Row],[Mean schooling ]]/15 -> 0.56033333 | K14: =(HDI_Data5[[#This Row],[Life Expectancy ]]-20)/65 -> 0.81261538 | L14: =(HDI_Data5[[#This Row],[EYSI]]+HDI_Data5[[#This Row],[MYSI]])/2 -> 0.66627778 | M14: =( LN( HDI_Data5[[#This Row],[GNI per capita (USD)]] ) - LN(100) ) / ( LN(75000) - LN(100) ) -> 0.62398552 | N14: =POWER((HDI_Data5[[#This Row],[Health Index]]*HDI_Data5[[#This Row],[Education Index]]*HDI_Data5[[#This Row],[Income Index]]), 1/3) -> 0.69647408
A15: Region X | B15: 2018 | C15: Female | D15: 73.15 | E15: 13.29 | F15: 8.749 | G15: 342099.24 | H15: =G15/VLOOKUP(B15, exchange_rates6[], 2, FALSE) -> 6496.3775 | I15: =HDI_Data5[[#This Row],[Expected Schooling ]]/18 -> 0.73833333 | J15: =HDI_Data5[[#This Row],[Mean schooling ]]/15 -> 0.58326667 | K15: =(HDI_Data5[[#This Row],[Life Expectancy ]]-20)/65 -> 0.81769231 | L15: =(HDI_Data5[[#This Row],[EYSI]]+HDI_Data5[[#This Row],[MYSI]])/2 -> 0.6608 | M15: =( LN( HDI_Data5[[#This Row],[GNI per capita (USD)]] ) - LN(100) ) / ( LN(75000) - LN(100) ) -> 0.63048092 | N15: =POWER((HDI_Data5[[#This Row],[Health Index]]*HDI_Data5[[#This Row],[Education Index]]*HDI_Data5[[#This Row],[Income Index]]), 1/3) -> 0.69841029
A16: Region XI | B16: 2018 | C16: Female | D16: 74.5 | E16: 13.01 | F16: 8.454 | G16: 305240.77 | H16: =G16/VLOOKUP(B16, exchange_rates6[], 2, FALSE) -> 5796.4446 | I16: =HDI_Data5[[#This Row],[Expected Schooling ]]/18 -> 0.72277778 | J16: =HDI_Data5[[#This Row],[Mean schooling ]]/15 -> 0.5636 | K16: =(HDI_Data5[[#This Row],[Life Expectancy ]]-20)/65 -> 0.83846154 | L16: =(HDI_Data5[[#This Row],[EYSI]]+HDI_Data5[[#This Row],[MYSI]])/2 -> 0.64318889 | M16: =( LN( HDI_Data5[[#This Row],[GNI per capita (USD)]] ) - LN(100) ) / ( LN(75000) - LN(100) ) -> 0.61326056 | N16: =POWER((HDI_Data5[[#This Row],[Health Index]]*HDI_Data5[[#This Row],[Education Index]]*HDI_Data5[[#This Row],[Income Index]]), 1/3) -> 0.69154785
A17: Region XII | B17: 2018 | C17: Female | D17: 70.36 | E17: 12.95 | F17: 8.058 | G17: 288040.44 | H17: =G17/VLOOKUP(B17, exchange_rates6[], 2, FALSE) -> 5469.8146 | I17: =HDI_Data5[[#This Row],[Expected Schooling ]]/18 -> 0.71944444 | J17: =HDI_Data5[[#This Row],[Mean schooling ]]/15 -> 0.5372 | K17: =(HDI_Data5[[#This Row],[Life Expectancy ]]-20)/65 -> 0.77476923 | L17: =(HDI_Data5[[#This Row],[EYSI]]+HDI_Data5[[#This Row],[MYSI]])/2 -> 0.62832222 | M17: =( LN( HDI_Data5[[#This Row],[GNI per capita (USD)]] ) - LN(100) ) / ( LN(75000) - LN(100) ) -> 0.60449933 | N17: =POWER((HDI_Data5[[#This Row],[Health Index]]*HDI_Data5[[#This Row],[Education Index]]*HDI_Data5[[#This Row],[Income Index]]), 1/3) -> 0.66514582
A18: Region XIII | B18: 2018 | C18: Female | D18: 73.89 | E18: 13.3 | F18: 8.583 | G18: 357130.36 | H18: =G18/VLOOKUP(B18, exchange_rates6[], 2, FALSE) -> 6781.8147 | I18: =HDI_Data5[[#This Row],[Expected Schooling ]]/18 -> 0.73888889 | J18: =HDI_Data5[[#This Row],[Mean schooling ]]/15 -> 0.5722 | K18: =(HDI_Data5[[#This Row],[Life Expectancy ]]-20)/65 -> 0.82907692 | L18: =(HDI_Data5[[#This Row],[EYSI]]+HDI_Data5[[#This Row],[MYSI]])/2 -> 0.65554444 | M18: =( LN( HDI_Data5[[#This Row],[GNI per capita (USD)]] ) - LN(100) ) / ( LN(75000) - LN(100) ) -> 0.63697631 | N18: =POWER((HDI_Data5[[#This Row],[Health Index]]*HDI_Data5[[#This Row],[Education Index]]*HDI_Data5[[#This Row],[Income Index]]), 1/3) -> 0.70216646
... A171: Region XIII | B171: 2022 | C171: Male | D171: 71.53 | E171: 12.62 | F171: 8.033 | G171: 612739.69 | H171: =G171/VLOOKUP(B171, exchange_rates6[], 2, FALSE) -> 11247.058 | I171: =HDI_Data5[[#This Row],[Expected Schooling ]]/18 -> 0.70111111 | J171: =HDI_Data5[[#This Row],[Mean schooling ]]/15 -> 0.53553333 | K171: =(HDI_Data5[[#This Row],[Life Expectancy ]]-20)/65 -> 0.79276923 | L171: =(HDI_Data5[[#This Row],[EYSI]]+HDI_Data5[[#This Row],[MYSI]])/2 -> 0.61832222 | M171: =( LN( HDI_Data5[[#This Row],[GNI per capita (USD)]] ) - LN(100) ) / ( LN(75000) - LN(100) ) -> 0.71338964 | N171: =POWER((HDI_Data5[[#This Row],[Health Index]]*HDI_Data5[[#This Row],[Education Index]]*HDI_Data5[[#This Row],[Income Index]]), 1/3) -> 0.70452457
